Workbook

Sheet Entry Sheet
A1: 2026 World Cup Competition
B3: Select a group winner for each group (2 points per correct answer)
B5: Group A | F5: Group B | J5: Group C
B6: Mexico | F6: Canada | J6: Brazil
B7: South Africa | F7: Bosnia & Herzegovina | J7: Morocco
B8: South Korea | F8: Qatar | J8: Haiti
B9: Czechia | F9: Switzerland | J9: Scotland
B11: Group D | F11: Group E | J11: Group F
B12: USA | F12: Germany | J12: Netherlands
B13: Paraguay | F13: Curacao | J13: Japan
B14: Australia | F14: Ivory Coast | J14: Sweden
B15: Turkey | F15: Ecuador | J15: Tunisia
B17: Group G | F17: Group H | J17: Group I
B18: Belgium | F18: Spain | J18: France
... B27: Jordan | F27: Colombia | J27: Panama
B29: Predict the four semi finalist teams (2 points per correct answer)
B43: Predict the two finalist teams (2 points per correct answer)
B51: Predict the World Cup winner (2 points per correct answer)
B56: Predict the Golden Boot winner (2 points per correct answer)
B61: Predict the first team to have a red card (2 points per correct answer)
B66: Predict the total number of goals scored in the whole World Cup (Tie breaker question)
B73: Mexico
B74: South Africa
B75: South Korea
B76: Czechia
B77: Canada
B78: Bosnia & Herzegovina
... B120: Panama

Sheet Games
A1: Date | B1: Home | C1: Score | E1: Away | G1: Goals: | H1: =SUM(C2:D105) -> 38
A2: 46184 | B2: Mexico | C2: 2 | D2: 0 | E2: South Africa | F2: SA first red card.
A3: 46185 | B3: South Korea | C3: 2 | D3: 1 | E3: Czechia
A4: 46185 | B4: Canada | C4: 1 | D4: 1 | E4: Bosnia & Herzegovina
A5: 46186 | B5: USA | C5: 4 | D5: 1 | E5: Paraguay
A6: 46186 | B6: Qatar | C6: 1 | D6: 1 | E6: Switzerland
A7: 46186 | B7: Brazil | C7: 1 | D7: 1 | E7: Morocco
A8: 46187 | B8: Haiti | C8: 0 | D8: 1 | E8: Scotland
A9: 46187 | B9: Australia | C9: 2 | D9: 0 | E9: Turkey
A10: 46187 | B10: Germany | C10: 7 | D10: 1 | E10: Curacao
A11: 46187 | B11: Netherlands | C11: 2 | D11: 2 | E11: Japan
A12: 46188 | B12: Ivory Coast | C12: 1 | D12: 0 | E12: Ecuador
A13: 46188 | B13: Sweden | C13: 5 | D13: 1 | E13: Tunisia
A14: 46188 | B14: Spain | C14: 0 | D14: 0 | E14: Cape Verde
A15: 46188 | B15: Belgium | E15: Egypt
A16: 46188 | B16: Saudi Arabia | E16: Uruguay
A17: 46189 | B17: Iran | E17: New Zealand
A18: 46189 | B18: France | E18: Senegal
A19: 46189 | B19: Iraq | E19: Norway
A20: 46190 | B20: Argentina | E20: Algeria
A21: 46190 | B21: Austria | E21: Jordan
A22: 46190 | B22: Portugal | E22: DR Congo
A23: 46190 | B23: England | E23: Croatia
A24: 46191 | B24: Ghana | E24: Panama
A25: 46191 | B25: Uzbekistan | E25: Colombia
A26: 46191 | B26: Czechia | E26: South Africa
... A73: 46201 | B73: Jordan | E73: Argentina
A74: 46201
A75: 46202
A76: 46202
A77: 46203
A78: 46203
A79: 46203
A80: 46204
A81: 46204
A82: 46204
A83: 46205
A84: 46205
A85: 46206
... A105: 46222

Sheet Entries
A1: Participant | B1: Group A Winner | C1: Group B Winner | D1: Group C Winner | E1: Group D Winner | F1: Group E Winner | G1: Group F Winner | H1: Group G Winner | I1: Group H Winner | J1: Group I Winner | K1: Group J Winner | L1: Group K Winner | M1: Group L Winner | N1: Semi-Finalist 1 | O1: Semi-Finalist 2 | P1: Semi-Finalist 3 | Q1: Semi-Finalist 4 | R1: Finalist 1 | S1: Finalist 2 | T1: Tournament Winner | U1: Golden Boot Winner | V1: First Red Card Team | W1: Tie-Break Total Goals | X1: Paid | Y1: Payment Link
A2: Gary Bebbington | B2: Mexico | C2: Switzerland | D2: Brazil | E2: Turkey | F2: Germany | G2: Netherlands | H2: Belgium | I2: Spain | J2: France | K2: Argentina | L2: Portugal | M2: England | N2: Brazil | O2: France | P2: Argentina | Q2: Spain | R2: Argentina | S2: Spain | T2: Spain | U2: Kylian Mbappe | V2: Bosnia & Herzegovina | W2: 250 | X2: Y | Y2: https://pay.sumup.com/b2c/X4M5URQIEI
A3: Liam Page | B3: Mexico | C3: Switzerland | D3: Brazil | E3: Paraguay | F3: Germany | G3: Netherlands | H3: Belgium | I3: Spain | J3: France | K3: Argentina | L3: Portugal | M3: England | N3: Spain | O3: France | P3: England | Q3: Germany | R3: France | S3: England | T3: France | U3: Harry Kane | V3: Paraguay | W3: 50 | X3: Y | Y3: https://pay.sumup.com/b2c/XUVBKRQD4U
A4: Andy Rutter | B4: Mexico | C4: Switzerland | D4: Brazil | E4: Turkey | F4: Germany | G4: Netherlands | H4: Belgium | I4: Spain | J4: France | K4: Argentina | L4: Portugal | M4: England | N4: Argentina | O4: France | P4: Brazil | Q4: Spain | R4: France | S4: Argentina | T4: France | U4: Kylian Mbappe | V4: Haiti | W4: 309 | X4: Y | Y4: https://pay.sumup.com/b2c/XIUR59CS9V
A5: Glyn Davies | B5: Mexico | C5: Bosnia & Herzegovina | D5: Brazil | E5: Turkey | F5: Germany | G5: Tunisia | H5: Belgium | I5: Spain | J5: France | K5: Argentina | L5: Portugal | M5: England | N5: Brazil | O5: Germany | P5: Spain | Q5: Argentina | R5: Germany | S5: Argentina | T5: Argentina | U5: Lautaro Martinez | V5: South Africa | W5: 205 | X5: Y | Y5: https://pay.sumup.com/b2c/XJ2OG3R9ZY
A6: Mr Zee | B6: Mexico | C6: Canada | D6: Brazil | E6: USA | F6: Ivory Coast | G6: Japan | H6: Belgium | I6: Spain | J6: France | K6: Argentina | L6: Portugal | M6: England | N6: Brazil | O6: USA | P6: Argentina | Q6: England | R6: Argentina | S6: USA | T6: Argentina | U6: Lamine Yamal | V6: Haiti | W6: 99 | X6: N
A7: Darren Moore | B7: Mexico | C7: Switzerland | D7: Brazil | E7: USA | F7: Germany | G7: Netherlands | H7: Belgium | I7: Spain | J7: France | K7: Argentina | L7: Portugal | M7: England | N7: England | O7: Germany | P7: Spain | Q7: France | R7: England | S7: Spain | T7: England | U7: Ollie Watkins | V7: Paraguay | W7: 235 | X7: Y | Y7: https://pay.sumup.com/b2c/XVJHXAUHPW
A8: Andrew Lee | B8: Mexico | C8: Switzerland | D8: Brazil | E8: Paraguay | F8: Germany | G8: Netherlands | H8: Belgium | I8: Spain | J8: France | K8: Argentina | L8: Portugal | M8: England | N8: Brazil | O8: Germany | P8: Spain | Q8: France | R8: Spain | S8: Brazil | T8: Brazil | U8: Kylian Mbappe | V8: South Africa | W8: 173 | X8: Y | Y8: https://pay.sumup.com/b2c/XD4XNCDO4A
A9: Claire Doughty | B9: Mexico | C9: Switzerland | D9: Brazil | E9: USA | F9: Germany | G9: Netherlands | H9: Belgium | I9: Spain | J9: France | K9: Argentina | L9: Portugal | M9: England | N9: Spain | O9: France | P9: Argentina | Q9: England | R9: Spain | S9: France | T9: Spain | U9: Kylian Mbappe | V9: South Africa | W9: 302 | X9: Y | Y9: https://pay.sumup.com/b2c/X47APG4IKV
A10: Andrew Hayes | B10: South Korea | C10: Switzerland | D10: Brazil | E10: USA | F10: Germany | G10: Netherlands | H10: Belgium | I10: Spain | J10: France | K10: Argentina | L10: Portugal | M10: England | N10: Brazil | O10: Germany | P10: Argentina | Q10: Spain | R10: Brazil | S10: Spain | T10: Spain | U10: Vinicius Junior | V10: Mexico | W10: 235 | X10: Y | Y10: https://pay.sumup.com/b2c/XIMFLHNUIF
A11: Lindsay Berry | B11: Mexico | C11: Switzerland | D11: Brazil | E11: Turkey | F11: Germany | G11: Netherlands | H11: Belgium | I11: Spain | J11: France | K11: Argentina | L11: Portugal | M11: England | N11: Brazil | O11: Spain | P11: Argentina | Q11: Mexico | R11: Brazil | S11: Argentina | T11: Argentina | U11: Naymer Junior | V11: DR Congo | W11: 285 | X11: Y | Y11: https://pay.sumup.com/b2c/XBQYQN61Z4
A12: Derek Clayton | B12: Mexico | C12: Switzerland | D12: Brazil | E12: USA | F12: Germany | G12: Japan | H12: Belgium | I12: Spain | J12: France | K12: Argentina | L12: Portugal | M12: England | N12: France | O12: Germany | P12: Argentina | Q12: Brazil | R12: France | S12: Brazil | T12: Brazil | U12: Julian Alvarez | V12: Czechia | W12: 350 | X12: Y | Y12: https://pay.sumup.com/b2c/X0FQYKI1YA
A13: Sophie Hayes | B13: South Korea | C13: Switzerland | D13: Brazil | E13: USA | F13: Germany | G13: Netherlands | H13: Belgium | I13: Spain | J13: France | K13: Argentina | L13: Portugal | M13: England | N13: Argentina | O13: Spain | P13: France | Q13: England | R13: England | S13: Argentina | T13: England | U13: Harry Kane | V13: Argentina | W13: 180 | X13: Y | Y13: https://pay.sumup.com/b2c/XIJCN762DV
A14: Colin Kudrycz | B14: Mexico | C14: Switzerland | D14: Brazil | E14: Turkey | F14: Ivory Coast | G14: Japan | H14: Belgium | I14: Spain | J14: France | K14: Argentina | L14: Colombia | M14: England | N14: Brazil | O14: Ivory Coast | P14: Portugal | Q14: Brazil | R14: Portugal | S14: Brazil | T14: Brazil | U14: Vinicius Junior | V14: Curacao | W14: 220 | X14: Y | Y14: https://pay.sumup.com/b2c/XUQLC9VJ3B
A15: Paul Roberts | B15: Mexico | C15: Switzerland | D15: Brazil | E15: Turkey | F15: Germany | G15: Japan | H15: Belgium | I15: Spain | J15: France | K15: Argentina | L15: Portugal | M15: England | N15: Brazil | O15: Portugal | P15: France | Q15: Spain | R15: Spain | S15: Brazil | T15: Brazil | U15: Harry Kane | V15: South Africa | W15: 160 | X15: Y | Y15: https://pay.sumup.com/b2c/XO2JXR9DPY
A16: Brian Varney | B16: South Korea | C16: Switzerland | D16: Brazil | E16: USA | F16: Germany | G16: Japan | H16: Egypt | I16: Spain | J16: France | K16: Argentina | L16: Portugal | M16: England | N16: France | O16: Spain | P16: England | Q16: Argentina | R16: England | S16: France | T16: England | U16: Harry Kane | V16: Haiti | W16: 281 | X16: Y | Y16: https://pay.sumup.com/b2c/X9A0WRUQ3U
A17: Nick Davis | B17: Mexico | C17: Switzerland | D17: Brazil | E17: Paraguay | F17: Ecuador | G17: Netherlands | H17: Belgium | I17: Spain | J17: France | K17: Argentina | L17: Portugal | M17: England | N17: Portugal | O17: Argentina | P17: France | Q17: Spain | R17: Spain | S17: Argentina | T17: Spain | U17: Kylian Mbappe | V17: South Africa | W17: 204 | X17: Y | Y17: https://pay.sumup.com/b2c/XKGC50ZSFQ
A18: Chris Varney | B18: Mexico | C18: Switzerland | D18: Brazil | E18: USA | F18: Germany | G18: Netherlands | H18: Belgium | I18: Spain | J18: France | K18: Argentina | L18: Portugal | M18: England | N18: Spain | O18: France | P18: Argentina | Q18: England | R18: Spain | S18: France | T18: France | U18: Lamine Yamal | V18: USA | W18: 238 | X18: Y | Y18: https://pay.sumup.com/b2c/X77QVLNIMG
... A22: David Brookes | B22: Mexico | C22: Switzerland | D22: Brazil | E22: Paraguay | F22: Germany | G22: Netherlands | H22: Belgium | I22: Spain | J22: France | K22: Argentina | L22: Portugal | M22: England | N22: France | O22: Spain | P22: Brazil | Q22: England | R22: Brazil | S22: Spain | T22: Brazil | U22: Harry Kane | V22: Scotland | W22: 211 | X22: Y | Y22: https://pay.sumup.com/b2c/XDJTC4BQMG
A23: Alan Bennett | B23: - | C23: - | D23: - | E23: - | F23: - | G23: - | H23: - | I23: - | J23: - | K23: - | L23: - | M23: - | N23: - | O23: - | P23: - | Q23: - | R23: - | S23: - | T23: - | U23: - | V23: - | W23: - | X23: Y | Y23: https://pay.sumup.com/b2c/XQ6K8IV83R
A24: Matthew Varney | B24: Czechia | C24: Switzerland | D24: Brazil | E24: USA | F24: Germany | G24: Netherlands | H24: Belgium | I24: Spain | J24: France | K24: Argentina | L24: Portugal | M24: England | N24: France | O24: Spain | P24: Brazil | Q24: Argentina | R24: Brazil | S24: Spain | T24: Spain | U24: Kylian Mbappe | V24: Ecuador | W24: 223 | X24: Y | Y24: https://pay.sumup.com/b2c/X7XMJ3FOP3
A25: Oliver Nay | B25: Mexico | C25: Switzerland | D25: Brazil | E25: Turkey | F25: Germany | G25: Netherlands | H25: Belgium | I25: Spain | J25: France | K25: Argentina | L25: Portugal | M25: England | N25: Spain | O25: Brazil | P25: England | Q25: France | R25: England | S25: France | T25: England | U25: Harry Kane | V25: Bosnia & Herzegovina | W25: 83 | X25: Y | Y25: https://pay.sumup.com/b2c/X841APLCIR
A26: Stephen Roberts | B26: Mexico | C26: Switzerland | D26: Brazil | E26: Paraguay | F26: Germany | G26: Netherlands | H26: Belgium | I26: Spain | J26: France | K26: Argentina | L26: Portugal | M26: England | N26: Spain | O26: France | P26: England | Q26: Argentina | R26: Spain | S26: France | T26: France | U26: Michael Olise | V26: Colombia | W26: 102 | X26: Y | Y26: https://pay.sumup.com/b2c/XRE3HFE7O5
A27: Ethan Yates | B27: Mexico | C27: Switzerland | D27: Brazil | E27: Turkey | F27: Germany | G27: Netherlands | H27: Belgium | I27: Spain | J27: France | K27: Argentina | L27: Portugal | M27: England | N27: France | O27: Spain | P27: Brazil | Q27: England | R27: France | S27: Spain | T27: France | U27: Kylian Mbappe | V27: South Korea | W27: 265 | X27: Y | Y27: https://pay.sumup.com/b2c/XLVKX1KVGO
A28: Neil Keelan | B28: Mexico | C28: Switzerland | D28: Brazil | E28: USA | F28: Germany | G28: Netherlands | H28: Belgium | I28: Spain | J28: France | K28: Argentina | L28: Portugal | M28: England | N28: France | O28: Brazil | P28: Spain | Q28: Argentina | R28: Spain | S28: Argentina | T28: Argentina | U28: Julian Alvarez | V28: South Africa | W28: 260 | X28: Y | Y28: https://pay.sumup.com/b2c/XA11GKL7S9
A29: Terresa Baker | B29: Mexico | C29: Bosnia & Herzegovina | D29: Brazil | E29: Paraguay | F29: Germany | G29: Japan | H29: Belgium | I29: Spain | J29: France | K29: Argentina | L29: Portugal | M29: England | N29: Mexico | O29: Brazil | P29: Spain | Q29: France | R29: Spain | S29: France | T29: France | U29: Harry Kane | V29: Jordan | W29: 242 | X29: Y | Y29: https://pay.sumup.com/b2c/XBUB3SZ21W
A30: Steph Cawte | B30: Mexico | C30: Switzerland | D30: Brazil | E30: Paraguay | F30: Germany | G30: Netherlands | H30: Belgium | I30: Spain | J30: France | K30: Argentina | L30: Portugal | M30: England | N30: France | O30: Spain | P30: England | Q30: Argentina | R30: Spain | S30: France | T30: Spain | U30: Lamine Yamal | V30: Senegal | W30: 169 | X30: Y | Y30: https://pay.sumup.com/b2c/X0URRRMLYI
A31: Sam Flower | B31: Mexico | C31: Canada | D31: Brazil | E31: USA | F31: Germany | G31: Netherlands | H31: Belgium | I31: Spain | J31: France | K31: Argentina | L31: Portugal | M31: England | N31: France | O31: Argentina | P31: Spain | Q31: Portugal | R31: Spain | S31: France | T31: Spain | U31: Kylian Mbappe | V31: Brazil | W31: 203 | X31: Y | Y31: https://pay.sumup.com/b2c/X4O52Y8PEV
A32: Martin Fallon | B32: Mexico | C32: Switzerland | D32: Brazil | E32: Turkey | F32: Germany | G32: Netherlands | H32: Belgium | I32: Spain | J32: France | K32: Argentina | L32: Portugal | M32: Croatia | N32: Germany | O32: Belgium | P32: England | Q32: Portugal | R32: Belgium | S32: Portugal | T32: Portugal | U32: Harry Kane | V32: Qatar | W32: 291 | X32: Y | Y32: https://pay.sumup.com/b2c/XQWR240BR3
A33: Ed Burthem | B33: Mexico | C33: Switzerland | D33: Brazil | E33: Turkey | F33: Germany | G33: Netherlands | H33: Belgium | I33: Spain | J33: France | K33: Argentina | L33: Portugal | M33: Croatia | N33: Portugal | O33: France | P33: Brazil | Q33: Spain | R33: France | S33: Portugal | T33: France | U33: Kylian Mbappe | V33: South Africa | W33: 218 | X33: Y | Y33: https://pay.sumup.com/b2c/XSP9GC1WZR
A34: Dylan Green | B34: Mexico | C34: Canada | D34: Brazil | E34: Turkey | F34: Germany | G34: Netherlands | H34: Belgium | I34: Spain | J34: France | K34: Argentina | L34: Portugal | M34: England | N34: England | O34: Spain | P34: Argentina | Q34: France | R34: France | S34: England | T34: England | U34: Harry Kane | V34: Paraguay | W34: 279 | X34: Y | Y34: https://pay.sumup.com/b2c/XLH7VOSPN7
A35: Matthew Green | B35: Mexico | C35: Switzerland | D35: Brazil | E35: Paraguay | F35: Germany | G35: Netherlands | H35: Belgium | I35: Spain | J35: France | K35: Argentina | L35: Portugal | M35: England | N35: England | O35: Argentina | P35: France | Q35: Spain | R35: England | S35: France | T35: England | U35: Harry Kane | V35: Spain | W35: 14 | X35: Y | Y35: https://pay.sumup.com/b2c/XN5XZOM95H
... A42: Andrew Brown | B42: South Korea | C42: Switzerland | D42: Brazil | E42: Turkey | F42: Germany | G42: Netherlands | H42: Belgium | I42: Spain | J42: France | K42: Argentina | L42: Portugal | M42: England | N42: Spain | O42: Netherlands | P42: England | Q42: Portugal | R42: Netherlands | S42: Portugal | T42: Netherlands | U42: Harry Kane | V42: South Africa | W42: 373 | X42: Y | Y42: https://pay.sumup.com/b2c/X1AUMMKITX
A43: Aid Corker | B43: Mexico | C43: Switzerland | D43: Brazil | E43: Turkey | F43: Germany | G43: Netherlands | H43: Belgium | I43: Spain | J43: France | K43: Argentina | L43: Portugal | M43: England | N43: Brazil | O43: France | P43: Germany | Q43: Spain | R43: Brazil | S43: France | T43: France | U43: Michael Olise | V43: Uruguay | W43: 243 | X43: N

Sheet Correct Answers
A1: Question | B1: Correct Answer
A2: Group A Winner
A3: Group B Winner
A4: Group C Winner
A5: Group D Winner
A6: Group E Winner
A7: Group F Winner
A8: Group G Winner
A9: Group H Winner
A10: Group I Winner
A11: Group J Winner
A12: Group K Winner
A13: Group L Winner
... A21: Golden Boot Winner
A22: First Red Card Team | B22: South Africa
A23: Tie-Break Total Goals | B23: =Games!H1 -> 38

Sheet Scoring
A1: Participant | B1: Score | E1: Group A Winner | F1: Group B Winner | G1: Group C Winner | H1: Group D Winner | I1: Group E Winner | J1: Group F Winner | K1: Group G Winner | L1: Group H Winner | M1: Group I Winner | N1: Group J Winner | O1: Group K Winner | P1: Group L Winner | Q1: Semi-Finalist | R1: Finalist | S1: Tournament Winner | T1: Golden Boot Winner | U1: First Red Card Team | V1: Goal Diff.
A2: =Entries!A2 -> Gary Bebbington | B2: =SUM(E2:U2) -> 0 | E2: =IF(Entries!B2='Correct Answers'!B2,2,0) -> 0 | F2: =IF(Entries!C2='Correct Answers'!B3,2,0) -> 0 | G2: =IF(Entries!D2='Correct Answers'!B4,2,0) -> 0 | H2: =IF(Entries!E2='Correct Answers'!B5,2,0) -> 0 | I2: =IF(Entries!F2='Correct Answers'!B6,2,0) -> 0 | J2: =IF(Entries!G2='Correct Answers'!B7,2,0) -> 0 | K2: =IF(Entries!H2='Correct Answers'!B8,2,0) -> 0 | L2: =IF(Entries!I2='Correct Answers'!B9,2,0) -> 0 | M2: =IF(Entries!J2='Correct Answers'!B10,2,0) -> 0 | N2: =IF(Entries!K2='Correct Answers'!B11,2,0) -> 0 | O2: =IF(Entries!L2='Correct Answers'!B12,2,0) -> 0 | P2: =IF(Entries!M2='Correct Answers'!B13,2,0) -> 0 | Q2: =2*(IF(Entries!N2='Correct Answers'!B14,1,0)+IF(Entries!O2='Correct Answers'!B15,1,0)+IF(Entries!P2='Correct Answers'!B16,1,0)+IF(Entries!Q2='Correct Answers'!B17,1,0)) -> 0 | R2: =2*(IF(Entries!R2='Correct Answers'!B18,1,0)+IF(Entries!S2='Correct Answers'!B19,1,0)) -> 0 | S2: =IF(Entries!T2='Correct Answers'!B20,2,0) -> 0 | T2: =IF(Entries!U2='Correct Answers'!B21,2,0) -> 0 | U2: =IF(Entries!V2='Correct Answers'!B22,2,0) -> 0 | V2: =Entries!W2-'Correct Answers'!B23 -> 212
A3: =Entries!A3 -> Liam Page | B3: =SUM(E3:U3) -> 0 | E3: =IF(Entries!B3='Correct Answers'!B2,2,0) -> 0 | F3: =IF(Entries!C3='Correct Answers'!B3,2,0) -> 0 | G3: =IF(Entries!D3='Correct Answers'!B4,2,0) -> 0 | H3: =IF(Entries!E3='Correct Answers'!B5,2,0) -> 0 | I3: =IF(Entries!F3='Correct Answers'!B6,2,0) -> 0 | J3: =IF(Entries!G3='Correct Answers'!B7,2,0) -> 0 | K3: =IF(Entries!H3='Correct Answers'!B8,2,0) -> 0 | L3: =IF(Entries!I3='Correct Answers'!B9,2,0) -> 0 | M3: =IF(Entries!J3='Correct Answers'!B10,2,0) -> 0 | N3: =IF(Entries!K3='Correct Answers'!B11,2,0) -> 0 | O3: =IF(Entries!L3='Correct Answers'!B12,2,0) -> 0 | P3: =IF(Entries!M3='Correct Answers'!B13,2,0) -> 0 | Q3: =2*(IF(Entries!N3='Correct Answers'!B14,1,0)+IF(Entries!O3='Correct Answers'!B15,1,0)+IF(Entries!P3='Correct Answers'!B16,1,0)+IF(Entries!Q3='Correct Answers'!B17,1,0)) -> 0 | R3: =2*(IF(Entries!R3='Correct Answers'!B18,1,0)+IF(Entries!S3='Correct Answers'!B19,1,0)) -> 0 | S3: =IF(Entries!T3='Correct Answers'!B20,2,0) -> 0 | T3: =IF(Entries!U3='Correct Answers'!B21,2,0) -> 0 | U3: =IF(Entries!V3='Correct Answers'!B22,2,0) -> 0 | V3: =Entries!W3-'Correct Answers'!B23 -> 12
A4: =Entries!A4 -> Andy Rutter | B4: =SUM(E4:U4) -> 0 | E4: =IF(Entries!B4='Correct Answers'!B2,2,0) -> 0 | F4: =IF(Entries!C4='Correct Answers'!B3,2,0) -> 0 | G4: =IF(Entries!D4='Correct Answers'!B4,2,0) -> 0 | H4: =IF(Entries!E4='Correct Answers'!B5,2,0) -> 0 | I4: =IF(Entries!F4='Correct Answers'!B6,2,0) -> 0 | J4: =IF(Entries!G4='Correct Answers'!B7,2,0) -> 0 | K4: =IF(Entries!H4='Correct Answers'!B8,2,0) -> 0 | L4: =IF(Entries!I4='Correct Answers'!B9,2,0) -> 0 | M4: =IF(Entries!J4='Correct Answers'!B10,2,0) -> 0 | N4: =IF(Entries!K4='Correct Answers'!B11,2,0) -> 0 | O4: =IF(Entries!L4='Correct Answers'!B12,2,0) -> 0 | P4: =IF(Entries!M4='Correct Answers'!B13,2,0) -> 0 | Q4: =2*(IF(Entries!N4='Correct Answers'!B14,1,0)+IF(Entries!O4='Correct Answers'!B15,1,0)+IF(Entries!P4='Correct Answers'!B16,1,0)+IF(Entries!Q4='Correct Answers'!B17,1,0)) -> 0 | R4: =2*(IF(Entries!R4='Correct Answers'!B18,1,0)+IF(Entries!S4='Correct Answers'!B19,1,0)) -> 0 | S4: =IF(Entries!T4='Correct Answers'!B20,2,0) -> 0 | T4: =IF(Entries!U4='Correct Answers'!B21,2,0) -> 0 | U4: =IF(Entries!V4='Correct Answers'!B22,2,0) -> 0 | V4: =Entries!W4-'Correct Answers'!B23 -> 271
A5: =Entries!A5 -> Glyn Davies | B5: =SUM(E5:U5) -> 2 | E5: =IF(Entries!B5='Correct Answers'!B2,2,0) -> 0 | F5: =IF(Entries!C5='Correct Answers'!B3,2,0) -> 0 | G5: =IF(Entries!D5='Correct Answers'!B4,2,0) -> 0 | H5: =IF(Entries!E5='Correct Answers'!B5,2,0) -> 0 | I5: =IF(Entries!F5='Correct Answers'!B6,2,0) -> 0 | J5: =IF(Entries!G5='Correct Answers'!B7,2,0) -> 0 | K5: =IF(Entries!H5='Correct Answers'!B8,2,0) -> 0 | L5: =IF(Entries!I5='Correct Answers'!B9,2,0) -> 0 | M5: =IF(Entries!J5='Correct Answers'!B10,2,0) -> 0 | N5: =IF(Entries!K5='Correct Answers'!B11,2,0) -> 0 | O5: =IF(Entries!L5='Correct Answers'!B12,2,0) -> 0 | P5: =IF(Entries!M5='Correct Answers'!B13,2,0) -> 0 | Q5: =2*(IF(Entries!N5='Correct Answers'!B14,1,0)+IF(Entries!O5='Correct Answers'!B15,1,0)+IF(Entries!P5='Correct Answers'!B16,1,0)+IF(Entries!Q5='Correct Answers'!B17,1,0)) -> 0 | R5: =2*(IF(Entries!R5='Correct Answers'!B18,1,0)+IF(Entries!S5='Correct Answers'!B19,1,0)) -> 0 | S5: =IF(Entries!T5='Correct Answers'!B20,2,0) -> 0 | T5: =IF(Entries!U5='Correct Answers'!B21,2,0) -> 0 | U5: =IF(Entries!V5='Correct Answers'!B22,2,0) -> 2 | V5: =Entries!W5-'Correct Answers'!B23 -> 167
A6: =Entries!A6 -> Mr Zee | B6: =SUM(E6:U6) -> 0 | E6: =IF(Entries!B6='Correct Answers'!B2,2,0) -> 0 | F6: =IF(Entries!C6='Correct Answers'!B3,2,0) -> 0 | G6: =IF(Entries!D6='Correct Answers'!B4,2,0) -> 0 | H6: =IF(Entries!E6='Correct Answers'!B5,2,0) -> 0 | I6: =IF(Entries!F6='Correct Answers'!B6,2,0) -> 0 | J6: =IF(Entries!G6='Correct Answers'!B7,2,0) -> 0 | K6: =IF(Entries!H6='Correct Answers'!B8,2,0) -> 0 | L6: =IF(Entries!I6='Correct Answers'!B9,2,0) -> 0 | M6: =IF(Entries!J6='Correct Answers'!B10,2,0) -> 0 | N6: =IF(Entries!K6='Correct Answers'!B11,2,0) -> 0 | O6: =IF(Entries!L6='Correct Answers'!B12,2,0) -> 0 | P6: =IF(Entries!M6='Correct Answers'!B13,2,0) -> 0 | Q6: =2*(IF(Entries!N6='Correct Answers'!B14,1,0)+IF(Entries!O6='Correct Answers'!B15,1,0)+IF(Entries!P6='Correct Answers'!B16,1,0)+IF(Entries!Q6='Correct Answers'!B17,1,0)) -> 0 | R6: =2*(IF(Entries!R6='Correct Answers'!B18,1,0)+IF(Entries!S6='Correct Answers'!B19,1,0)) -> 0 | S6: =IF(Entries!T6='Correct Answers'!B20,2,0) -> 0 | T6: =IF(Entries!U6='Correct Answers'!B21,2,0) -> 0 | U6: =IF(Entries!V6='Correct Answers'!B22,2,0) -> 0 | V6: =Entries!W6-'Correct Answers'!B23 -> 61
A7: =Entries!A7 -> Darren Moore | B7: =SUM(E7:U7) -> 0 | E7: =IF(Entries!B7='Correct Answers'!B2,2,0) -> 0 | F7: =IF(Entries!C7='Correct Answers'!B3,2,0) -> 0 | G7: =IF(Entries!D7='Correct Answers'!B4,2,0) -> 0 | H7: =IF(Entries!E7='Correct Answers'!B5,2,0) -> 0 | I7: =IF(Entries!F7='Correct Answers'!B6,2,0) -> 0 | J7: =IF(Entries!G7='Correct Answers'!B7,2,0) -> 0 | K7: =IF(Entries!H7='Correct Answers'!B8,2,0) -> 0 | L7: =IF(Entries!I7='Correct Answers'!B9,2,0) -> 0 | M7: =IF(Entries!J7='Correct Answers'!B10,2,0) -> 0 | N7: =IF(Entries!K7='Correct Answers'!B11,2,0) -> 0 | O7: =IF(Entries!L7='Correct Answers'!B12,2,0) -> 0 | P7: =IF(Entries!M7='Correct Answers'!B13,2,0) -> 0 | Q7: =2*(IF(Entries!N7='Correct Answers'!B14,1,0)+IF(Entries!O7='Correct Answers'!B15,1,0)+IF(Entries!P7='Correct Answers'!B16,1,0)+IF(Entries!Q7='Correct Answers'!B17,1,0)) -> 0 | R7: =2*(IF(Entries!R7='Correct Answers'!B18,1,0)+IF(Entries!S7='Correct Answers'!B19,1,0)) -> 0 | S7: =IF(Entries!T7='Correct Answers'!B20,2,0) -> 0 | T7: =IF(Entries!U7='Correct Answers'!B21,2,0) -> 0 | U7: =IF(Entries!V7='Correct Answers'!B22,2,0) -> 0 | V7: =Entries!W7-'Correct Answers'!B23 -> 197
A8: =Entries!A8 -> Andrew Lee | B8: =SUM(E8:U8) -> 2 | E8: =IF(Entries!B8='Correct Answers'!B2,2,0) -> 0 | F8: =IF(Entries!C8='Correct Answers'!B3,2,0) -> 0 | G8: =IF(Entries!D8='Correct Answers'!B4,2,0) -> 0 | H8: =IF(Entries!E8='Correct Answers'!B5,2,0) -> 0 | I8: =IF(Entries!F8='Correct Answers'!B6,2,0) -> 0 | J8: =IF(Entries!G8='Correct Answers'!B7,2,0) -> 0 | K8: =IF(Entries!H8='Correct Answers'!B8,2,0) -> 0 | L8: =IF(Entries!I8='Correct Answers'!B9,2,0) -> 0 | M8: =IF(Entries!J8='Correct Answers'!B10,2,0) -> 0 | N8: =IF(Entries!K8='Correct Answers'!B11,2,0) -> 0 | O8: =IF(Entries!L8='Correct Answers'!B12,2,0) -> 0 | P8: =IF(Entries!M8='Correct Answers'!B13,2,0) -> 0 | Q8: =2*(IF(Entries!N8='Correct Answers'!B14,1,0)+IF(Entries!O8='Correct Answers'!B15,1,0)+IF(Entries!P8='Correct Answers'!B16,1,0)+IF(Entries!Q8='Correct Answers'!B17,1,0)) -> 0 | R8: =2*(IF(Entries!R8='Correct Answers'!B18,1,0)+IF(Entries!S8='Correct Answers'!B19,1,0)) -> 0 | S8: =IF(Entries!T8='Correct Answers'!B20,2,0) -> 0 | T8: =IF(Entries!U8='Correct Answers'!B21,2,0) -> 0 | U8: =IF(Entries!V8='Correct Answers'!B22,2,0) -> 2 | V8: =Entries!W8-'Correct Answers'!B23 -> 135
A9: =Entries!A9 -> Claire Doughty | B9: =SUM(E9:U9) -> 2 | E9: =IF(Entries!B9='Correct Answers'!B2,2,0) -> 0 | F9: =IF(Entries!C9='Correct Answers'!B3,2,0) -> 0 | G9: =IF(Entries!D9='Correct Answers'!B4,2,0) -> 0 | H9: =IF(Entries!E9='Correct Answers'!B5,2,0) -> 0 | I9: =IF(Entries!F9='Correct Answers'!B6,2,0) -> 0 | J9: =IF(Entries!G9='Correct Answers'!B7,2,0) -> 0 | K9: =IF(Entries!H9='Correct Answers'!B8,2,0) -> 0 | L9: =IF(Entries!I9='Correct Answers'!B9,2,0) -> 0 | M9: =IF(Entries!J9='Correct Answers'!B10,2,0) -> 0 | N9: =IF(Entries!K9='Correct Answers'!B11,2,0) -> 0 | O9: =IF(Entries!L9='Correct Answers'!B12,2,0) -> 0 | P9: =IF(Entries!M9='Correct Answers'!B13,2,0) -> 0 | Q9: =2*(IF(Entries!N9='Correct Answers'!B14,1,0)+IF(Entries!O9='Correct Answers'!B15,1,0)+IF(Entries!P9='Correct Answers'!B16,1,0)+IF(Entries!Q9='Correct Answers'!B17,1,0)) -> 0 | R9: =2*(IF(Entries!R9='Correct Answers'!B18,1,0)+IF(Entries!S9='Correct Answers'!B19,1,0)) -> 0 | S9: =IF(Entries!T9='Correct Answers'!B20,2,0) -> 0 | T9: =IF(Entries!U9='Correct Answers'!B21,2,0) -> 0 | U9: =IF(Entries!V9='Correct Answers'!B22,2,0) -> 2 | V9: =Entries!W9-'Correct Answers'!B23 -> 264
A10: =Entries!A10 -> Andrew Hayes | B10: =SUM(E10:U10) -> 0 | E10: =IF(Entries!B10='Correct Answers'!B2,2,0) -> 0 | F10: =IF(Entries!C10='Correct Answers'!B3,2,0) -> 0 | G10: =IF(Entries!D10='Correct Answers'!B4,2,0) -> 0 | H10: =IF(Entries!E10='Correct Answers'!B5,2,0) -> 0 | I10: =IF(Entries!F10='Correct Answers'!B6,2,0) -> 0 | J10: =IF(Entries!G10='Correct Answers'!B7,2,0) -> 0 | K10: =IF(Entries!H10='Correct Answers'!B8,2,0) -> 0 | L10: =IF(Entries!I10='Correct Answers'!B9,2,0) -> 0 | M10: =IF(Entries!J10='Correct Answers'!B10,2,0) -> 0 | N10: =IF(Entries!K10='Correct Answers'!B11,2,0) -> 0 | O10: =IF(Entries!L10='Correct Answers'!B12,2,0) -> 0 | P10: =IF(Entries!M10='Correct Answers'!B13,2,0) -> 0 | Q10: =2*(IF(Entries!N10='Correct Answers'!B14,1,0)+IF(Entries!O10='Correct Answers'!B15,1,0)+IF(Entries!P10='Correct Answers'!B16,1,0)+IF(Entries!Q10='Correct Answers'!B17,1,0)) -> 0 | R10: =2*(IF(Entries!R10='Correct Answers'!B18,1,0)+IF(Entries!S10='Correct Answers'!B19,1,0)) -> 0 | S10: =IF(Entries!T10='Correct Answers'!B20,2,0) -> 0 | T10: =IF(Entries!U10='Correct Answers'!B21,2,0) -> 0 | U10: =IF(Entries!V10='Correct Answers'!B22,2,0) -> 0 | V10: =Entries!W10-'Correct Answers'!B23 -> 197
A11: =Entries!A11 -> Lindsay Berry | B11: =SUM(E11:U11) -> 0 | E11: =IF(Entries!B11='Correct Answers'!B2,2,0) -> 0 | F11: =IF(Entries!C11='Correct Answers'!B3,2,0) -> 0 | G11: =IF(Entries!D11='Correct Answers'!B4,2,0) -> 0 | H11: =IF(Entries!E11='Correct Answers'!B5,2,0) -> 0 | I11: =IF(Entries!F11='Correct Answers'!B6,2,0) -> 0 | J11: =IF(Entries!G11='Correct Answers'!B7,2,0) -> 0 | K11: =IF(Entries!H11='Correct Answers'!B8,2,0) -> 0 | L11: =IF(Entries!I11='Correct Answers'!B9,2,0) -> 0 | M11: =IF(Entries!J11='Correct Answers'!B10,2,0) -> 0 | N11: =IF(Entries!K11='Correct Answers'!B11,2,0) -> 0 | O11: =IF(Entries!L11='Correct Answers'!B12,2,0) -> 0 | P11: =IF(Entries!M11='Correct Answers'!B13,2,0) -> 0 | Q11: =2*(IF(Entries!N11='Correct Answers'!B14,1,0)+IF(Entries!O11='Correct Answers'!B15,1,0)+IF(Entries!P11='Correct Answers'!B16,1,0)+IF(Entries!Q11='Correct Answers'!B17,1,0)) -> 0 | R11: =2*(IF(Entries!R11='Correct Answers'!B18,1,0)+IF(Entries!S11='Correct Answers'!B19,1,0)) -> 0 | S11: =IF(Entries!T11='Correct Answers'!B20,2,0) -> 0 | T11: =IF(Entries!U11='Correct Answers'!B21,2,0) -> 0 | U11: =IF(Entries!V11='Correct Answers'!B22,2,0) -> 0 | V11: =Entries!W11-'Correct Answers'!B23 -> 247
A12: =Entries!A12 -> Derek Clayton | B12: =SUM(E12:U12) -> 0 | E12: =IF(Entries!B12='Correct Answers'!B2,2,0) -> 0 | F12: =IF(Entries!C12='Correct Answers'!B3,2,0) -> 0 | G12: =IF(Entries!D12='Correct Answers'!B4,2,0) -> 0 | H12: =IF(Entries!E12='Correct Answers'!B5,2,0) -> 0 | I12: =IF(Entries!F12='Correct Answers'!B6,2,0) -> 0 | J12: =IF(Entries!G12='Correct Answers'!B7,2,0) -> 0 | K12: =IF(Entries!H12='Correct Answers'!B8,2,0) -> 0 | L12: =IF(Entries!I12='Correct Answers'!B9,2,0) -> 0 | M12: =IF(Entries!J12='Correct Answers'!B10,2,0) -> 0 | N12: =IF(Entries!K12='Correct Answers'!B11,2,0) -> 0 | O12: =IF(Entries!L12='Correct Answers'!B12,2,0) -> 0 | P12: =IF(Entries!M12='Correct Answers'!B13,2,0) -> 0 | Q12: =2*(IF(Entries!N12='Correct Answers'!B14,1,0)+IF(Entries!O12='Correct Answers'!B15,1,0)+IF(Entries!P12='Correct Answers'!B16,1,0)+IF(Entries!Q12='Correct Answers'!B17,1,0)) -> 0 | R12: =2*(IF(Entries!R12='Correct Answers'!B18,1,0)+IF(Entries!S12='Correct Answers'!B19,1,0)) -> 0 | S12: =IF(Entries!T12='Correct Answers'!B20,2,0) -> 0 | T12: =IF(Entries!U12='Correct Answers'!B21,2,0) -> 0 | U12: =IF(Entries!V12='Correct Answers'!B22,2,0) -> 0 | V12: =Entries!W12-'Correct Answers'!B23 -> 312
A13: =Entries!A13 -> Sophie Hayes | B13: =SUM(E13:U13) -> 0 | E13: =IF(Entries!B13='Correct Answers'!B2,2,0) -> 0 | F13: =IF(Entries!C13='Correct Answers'!B3,2,0) -> 0 | G13: =IF(Entries!D13='Correct Answers'!B4,2,0) -> 0 | H13: =IF(Entries!E13='Correct Answers'!B5,2,0) -> 0 | I13: =IF(Entries!F13='Correct Answers'!B6,2,0) -> 0 | J13: =IF(Entries!G13='Correct Answers'!B7,2,0) -> 0 | K13: =IF(Entries!H13='Correct Answers'!B8,2,0) -> 0 | L13: =IF(Entries!I13='Correct Answers'!B9,2,0) -> 0 | M13: =IF(Entries!J13='Correct Answers'!B10,2,0) -> 0 | N13: =IF(Entries!K13='Correct Answers'!B11,2,0) -> 0 | O13: =IF(Entries!L13='Correct Answers'!B12,2,0) -> 0 | P13: =IF(Entries!M13='Correct Answers'!B13,2,0) -> 0 | Q13: =2*(IF(Entries!N13='Correct Answers'!B14,1,0)+IF(Entries!O13='Correct Answers'!B15,1,0)+IF(Entries!P13='Correct Answers'!B16,1,0)+IF(Entries!Q13='Correct Answers'!B17,1,0)) -> 0 | R13: =2*(IF(Entries!R13='Correct Answers'!B18,1,0)+IF(Entries!S13='Correct Answers'!B19,1,0)) -> 0 | S13: =IF(Entries!T13='Correct Answers'!B20,2,0) -> 0 | T13: =IF(Entries!U13='Correct Answers'!B21,2,0) -> 0 | U13: =IF(Entries!V13='Correct Answers'!B22,2,0) -> 0 | V13: =Entries!W13-'Correct Answers'!B23 -> 142
A14: =Entries!A14 -> Colin Kudrycz | B14: =SUM(E14:U14) -> 0 | E14: =IF(Entries!B14='Correct Answers'!B2,2,0) -> 0 | F14: =IF(Entries!C14='Correct Answers'!B32,2,0) -> 0 | G14: =IF(Entries!D14='Correct Answers'!B4,2,0) -> 0 | H14: =IF(Entries!E14='Correct Answers'!B5,2,0) -> 0 | I14: =IF(Entries!F14='Correct Answers'!B6,2,0) -> 0 | J14: =IF(Entries!G14='Correct Answers'!B7,2,0) -> 0 | K14: =IF(Entries!H14='Correct Answers'!B8,2,0) -> 0 | L14: =IF(Entries!I14='Correct Answers'!B9,2,0) -> 0 | M14: =IF(Entries!J14='Correct Answers'!B10,2,0) -> 0 | N14: =IF(Entries!K14='Correct Answers'!B11,2,0) -> 0 | O14: =IF(Entries!L14='Correct Answers'!B12,2,0) -> 0 | P14: =IF(Entries!M14='Correct Answers'!B13,2,0) -> 0 | Q14: =2*(IF(Entries!N14='Correct Answers'!B14,1,0)+IF(Entries!O14='Correct Answers'!B15,1,0)+IF(Entries!P14='Correct Answers'!B16,1,0)+IF(Entries!Q14='Correct Answers'!B17,1,0)) -> 0 | R14: =2*(IF(Entries!R14='Correct Answers'!B18,1,0)+IF(Entries!S14='Correct Answers'!B19,1,0)) -> 0 | S14: =IF(Entries!T14='Correct Answers'!B20,2,0) -> 0 | T14: =IF(Entries!U14='Correct Answers'!B21,2,0) -> 0 | U14: =IF(Entries!V14='Correct Answers'!B22,2,0) -> 0 | V14: =Entries!W14-'Correct Answers'!B23 -> 182
A15: =Entries!A15 -> Paul Roberts | B15: =SUM(E15:U15) -> 2 | E15: =IF(Entries!B15='Correct Answers'!B2,2,0) -> 0 | F15: =IF(Entries!C15='Correct Answers'!B3,2,0) -> 0 | G15: =IF(Entries!D15='Correct Answers'!B4,2,0) -> 0 | H15: =IF(Entries!E15='Correct Answers'!B5,2,0) -> 0 | I15: =IF(Entries!F15='Correct Answers'!B6,2,0) -> 0 | J15: =IF(Entries!G15='Correct Answers'!B7,2,0) -> 0 | K15: =IF(Entries!H15='Correct Answers'!B8,2,0) -> 0 | L15: =IF(Entries!I15='Correct Answers'!B9,2,0) -> 0 | M15: =IF(Entries!J15='Correct Answers'!B10,2,0) -> 0 | N15: =IF(Entries!K15='Correct Answers'!B11,2,0) -> 0 | O15: =IF(Entries!L15='Correct Answers'!B12,2,0) -> 0 | P15: =IF(Entries!M15='Correct Answers'!B13,2,0) -> 0 | Q15: =2*(IF(Entries!N15='Correct Answers'!B14,1,0)+IF(Entries!O15='Correct Answers'!B15,1,0)+IF(Entries!P15='Correct Answers'!B16,1,0)+IF(Entries!Q15='Correct Answers'!B17,1,0)) -> 0 | R15: =2*(IF(Entries!R15='Correct Answers'!B18,1,0)+IF(Entries!S15='Correct Answers'!B19,1,0)) -> 0 | S15: =IF(Entries!T15='Correct Answers'!B20,2,0) -> 0 | T15: =IF(Entries!U15='Correct Answers'!B21,2,0) -> 0 | U15: =IF(Entries!V15='Correct Answers'!B22,2,0) -> 2 | V15: =Entries!W15-'Correct Answers'!B23 -> 122
A16: =Entries!A16 -> Brian Varney | B16: =SUM(E16:U16) -> 0 | E16: =IF(Entries!B16='Correct Answers'!B2,2,0) -> 0 | F16: =IF(Entries!C16='Correct Answers'!B3,2,0) -> 0 | G16: =IF(Entries!D16='Correct Answers'!B4,2,0) -> 0 | H16: =IF(Entries!E16='Correct Answers'!B5,2,0) -> 0 | I16: =IF(Entries!F16='Correct Answers'!B6,2,0) -> 0 | J16: =IF(Entries!G16='Correct Answers'!B7,2,0) -> 0 | K16: =IF(Entries!H16='Correct Answers'!B8,2,0) -> 0 | L16: =IF(Entries!I16='Correct Answers'!B9,2,0) -> 0 | M16: =IF(Entries!J16='Correct Answers'!B10,2,0) -> 0 | N16: =IF(Entries!K16='Correct Answers'!B11,2,0) -> 0 | O16: =IF(Entries!L16='Correct Answers'!B12,2,0) -> 0 | P16: =IF(Entries!M16='Correct Answers'!B13,2,0) -> 0 | Q16: =2*(IF(Entries!N16='Correct Answers'!B14,1,0)+IF(Entries!O16='Correct Answers'!B15,1,0)+IF(Entries!P16='Correct Answers'!B16,1,0)+IF(Entries!Q16='Correct Answers'!B17,1,0)) -> 0 | R16: =2*(IF(Entries!R16='Correct Answers'!B18,1,0)+IF(Entries!S16='Correct Answers'!B19,1,0)) -> 0 | S16: =IF(Entries!T16='Correct Answers'!B20,2,0) -> 0 | T16: =IF(Entries!U16='Correct Answers'!B21,2,0) -> 0 | U16: =IF(Entries!V16='Correct Answers'!B22,2,0) -> 0 | V16: =Entries!W16-'Correct Answers'!B23 -> 243
A17: =Entries!A17 -> Nick Davis | B17: =SUM(E17:U17) -> 2 | E17: =IF(Entries!B17='Correct Answers'!B2,2,0) -> 0 | F17: =IF(Entries!C17='Correct Answers'!B3,2,0) -> 0 | G17: =IF(Entries!D17='Correct Answers'!B4,2,0) -> 0 | H17: =IF(Entries!E17='Correct Answers'!B5,2,0) -> 0 | I17: =IF(Entries!F17='Correct Answers'!B6,2,0) -> 0 | J17: =IF(Entries!G17='Correct Answers'!B7,2,0) -> 0 | K17: =IF(Entries!H17='Correct Answers'!B8,2,0) -> 0 | L17: =IF(Entries!I17='Correct Answers'!B9,2,0) -> 0 | M17: =IF(Entries!J17='Correct Answers'!B10,2,0) -> 0 | N17: =IF(Entries!K17='Correct Answers'!B11,2,0) -> 0 | O17: =IF(Entries!L17='Correct Answers'!B12,2,0) -> 0 | P17: =IF(Entries!M17='Correct Answers'!B13,2,0) -> 0 | Q17: =2*(IF(Entries!N17='Correct Answers'!B14,1,0)+IF(Entries!O17='Correct Answers'!B15,1,0)+IF(Entries!P17='Correct Answers'!B16,1,0)+IF(Entries!Q17='Correct Answers'!B17,1,0)) -> 0 | R17: =2*(IF(Entries!R17='Correct Answers'!B18,1,0)+IF(Entries!S17='Correct Answers'!B19,1,0)) -> 0 | S17: =IF(Entries!T17='Correct Answers'!B20,2,0) -> 0 | T17: =IF(Entries!U17='Correct Answers'!B21,2,0) -> 0 | U17: =IF(Entries!V17='Correct Answers'!B22,2,0) -> 2 | V17: =Entries!W17-'Correct Answers'!B23 -> 166
A18: =Entries!A18 -> Chris Varney | B18: =SUM(E18:U18) -> 0 | E18: =IF(Entries!B18='Correct Answers'!B2,2,0) -> 0 | F18: =IF(Entries!C18='Correct Answers'!B3,2,0) -> 0 | G18: =IF(Entries!D18='Correct Answers'!B4,2,0) -> 0 | H18: =IF(Entries!E18='Correct Answers'!B5,2,0) -> 0 | I18: =IF(Entries!F18='Correct Answers'!B6,2,0) -> 0 | J18: =IF(Entries!G18='Correct Answers'!B7,2,0) -> 0 | K18: =IF(Entries!H18='Correct Answers'!B8,2,0) -> 0 | L18: =IF(Entries!I18='Correct Answers'!B9,2,0) -> 0 | M18: =IF(Entries!J18='Correct Answers'!B10,2,0) -> 0 | N18: =IF(Entries!K18='Correct Answers'!B11,2,0) -> 0 | O18: =IF(Entries!L18='Correct Answers'!B12,2,0) -> 0 | P18: =IF(Entries!M18='Correct Answers'!B13,2,0) -> 0 | Q18: =2*(IF(Entries!N18='Correct Answers'!B14,1,0)+IF(Entries!O18='Correct Answers'!B15,1,0)+IF(Entries!P18='Correct Answers'!B16,1,0)+IF(Entries!Q18='Correct Answers'!B17,1,0)) -> 0 | R18: =2*(IF(Entries!R18='Correct Answers'!B18,1,0)+IF(Entries!S18='Correct Answers'!B19,1,0)) -> 0 | S18: =IF(Entries!T18='Correct Answers'!B20,2,0) -> 0 | T18: =IF(Entries!U18='Correct Answers'!B21,2,0) -> 0 | U18: =IF(Entries!V18='Correct Answers'!B22,2,0) -> 0 | V18: =Entries!W18-'Correct Answers'!B23 -> 200
A19: =Entries!A19 -> Roy Roberts | B19: =SUM(E19:U19) -> 0 | E19: =IF(Entries!B19='Correct Answers'!B2,2,0) -> 0 | F19: =IF(Entries!C19='Correct Answers'!B3,2,0) -> 0 | G19: =IF(Entries!D19='Correct Answers'!B4,2,0) -> 0 | H19: =IF(Entries!E19='Correct Answers'!B5,2,0) -> 0 | I19: =IF(Entries!F19='Correct Answers'!B6,2,0) -> 0 | J19: =IF(Entries!G19='Correct Answers'!B7,2,0) -> 0 | K19: =IF(Entries!H19='Correct Answers'!B8,2,0) -> 0 | L19: =IF(Entries!I19='Correct Answers'!B9,2,0) -> 0 | M19: =IF(Entries!J19='Correct Answers'!B10,2,0) -> 0 | N19: =IF(Entries!K19='Correct Answers'!B11,2,0) -> 0 | O19: =IF(Entries!L19='Correct Answers'!B12,2,0) -> 0 | P19: =IF(Entries!M19='Correct Answers'!B13,2,0) -> 0 | Q19: =2*(IF(Entries!N19='Correct Answers'!B14,1,0)+IF(Entries!O19='Correct Answers'!B15,1,0)+IF(Entries!P19='Correct Answers'!B16,1,0)+IF(Entries!Q19='Correct Answers'!B17,1,0)) -> 0 | R19: =2*(IF(Entries!R19='Correct Answers'!B18,1,0)+IF(Entries!S19='Correct Answers'!B19,1,0)) -> 0 | S19: =IF(Entries!T19='Correct Answers'!B20,2,0) -> 0 | T19: =IF(Entries!U19='Correct Answers'!B21,2,0) -> 0 | U19: =IF(Entries!V19='Correct Answers'!B22,2,0) -> 0 | V19: =Entries!W19-'Correct Answers'!B23 -> 180
A20: =Entries!A20 -> Lee Hughes | B20: =SUM(E20:U20) -> 0 | E20: =IF(Entries!B20='Correct Answers'!B2,2,0) -> 0 | F20: =IF(Entries!C20='Correct Answers'!B3,2,0) -> 0 | G20: =IF(Entries!D20='Correct Answers'!B4,2,0) -> 0 | H20: =IF(Entries!E20='Correct Answers'!B5,2,0) -> 0 | I20: =IF(Entries!F20='Correct Answers'!B6,2,0) -> 0 | J20: =IF(Entries!G20='Correct Answers'!B7,2,0) -> 0 | K20: =IF(Entries!H20='Correct Answers'!B8,2,0) -> 0 | L20: =IF(Entries!I20='Correct Answers'!B9,2,0) -> 0 | M20: =IF(Entries!J20='Correct Answers'!B10,2,0) -> 0 | N20: =IF(Entries!K20='Correct Answers'!B11,2,0) -> 0 | O20: =IF(Entries!L20='Correct Answers'!B12,2,0) -> 0 | P20: =IF(Entries!M20='Correct Answers'!B13,2,0) -> 0 | Q20: =2*(IF(Entries!N20='Correct Answers'!B14,1,0)+IF(Entries!O20='Correct Answers'!B15,1,0)+IF(Entries!P20='Correct Answers'!B16,1,0)+IF(Entries!Q20='Correct Answers'!B17,1,0)) -> 0 | R20: =2*(IF(Entries!R20='Correct Answers'!B18,1,0)+IF(Entries!S20='Correct Answers'!B19,1,0)) -> 0 | S20: =IF(Entries!T20='Correct Answers'!B20,2,0) -> 0 | T20: =IF(Entries!U20='Correct Answers'!B21,2,0) -> 0 | U20: =IF(Entries!V20='Correct Answers'!B22,2,0) -> 0 | V20: =Entries!W20-'Correct Answers'!B23 -> 62
A21: =Entries!A21 -> Amanda Andrews | B21: =SUM(E21:U21) -> 2 | E21: =IF(Entries!B21='Correct Answers'!B2,2,0) -> 0 | F21: =IF(Entries!C21='Correct Answers'!B3,2,0) -> 0 | G21: =IF(Entries!D21='Correct Answers'!B4,2,0) -> 0 | H21: =IF(Entries!E21='Correct Answers'!B5,2,0) -> 0 | I21: =IF(Entries!F21='Correct Answers'!B6,2,0) -> 0 | J21: =IF(Entries!G21='Correct Answers'!B7,2,0) -> 0 | K21: =IF(Entries!H21='Correct Answers'!B8,2,0) -> 0 | L21: =IF(Entries!I21='Correct Answers'!B9,2,0) -> 0 | M21: =IF(Entries!J21='Correct Answers'!B10,2,0) -> 0 | N21: =IF(Entries!K21='Correct Answers'!B11,2,0) -> 0 | O21: =IF(Entries!L21='Correct Answers'!B12,2,0) -> 0 | P21: =IF(Entries!M21='Correct Answers'!B13,2,0) -> 0 | Q21: =2*(IF(Entries!N21='Correct Answers'!B14,1,0)+IF(Entries!O21='Correct Answers'!B15,1,0)+IF(Entries!P21='Correct Answers'!B16,1,0)+IF(Entries!Q21='Correct Answers'!B17,1,0)) -> 0 | R21: =2*(IF(Entries!R21='Correct Answers'!B18,1,0)+IF(Entries!S21='Correct Answers'!B19,1,0)) -> 0 | S21: =IF(Entries!T21='Correct Answers'!B20,2,0) -> 0 | T21: =IF(Entries!U21='Correct Answers'!B21,2,0) -> 0 | U21: =IF(Entries!V21='Correct Answers'!B22,2,0) -> 2 | V21: =Entries!W21-'Correct Answers'!B23 -> 202
A22: =Entries!A22 -> David Brookes | B22: =SUM(E22:U22) -> 0 | E22: =IF(Entries!B22='Correct Answers'!B2,2,0) -> 0 | F22: =IF(Entries!C22='Correct Answers'!B3,2,0) -> 0 | G22: =IF(Entries!D22='Correct Answers'!B4,2,0) -> 0 | H22: =IF(Entries!E22='Correct Answers'!B5,2,0) -> 0 | I22: =IF(Entries!F22='Correct Answers'!B6,2,0) -> 0 | J22: =IF(Entries!G22='Correct Answers'!B7,2,0) -> 0 | K22: =IF(Entries!H22='Correct Answers'!B8,2,0) -> 0 | L22: =IF(Entries!I22='Correct Answers'!B9,2,0) -> 0 | M22: =IF(Entries!J22='Correct Answers'!B10,2,0) -> 0 | N22: =IF(Entries!K22='Correct Answers'!B11,2,0) -> 0 | O22: =IF(Entries!L22='Correct Answers'!B12,2,0) -> 0 | P22: =IF(Entries!M22='Correct Answers'!B13,2,0) -> 0 | Q22: =2*(IF(Entries!N22='Correct Answers'!B14,1,0)+IF(Entries!O22='Correct Answers'!B15,1,0)+IF(Entries!P22='Correct Answers'!B16,1,0)+IF(Entries!Q22='Correct Answers'!B17,1,0)) -> 0 | R22: =2*(IF(Entries!R22='Correct Answers'!B18,1,0)+IF(Entries!S22='Correct Answers'!B19,1,0)) -> 0 | S22: =IF(Entries!T22='Correct Answers'!B20,2,0) -> 0 | T22: =IF(Entries!U22='Correct Answers'!B21,2,0) -> 0 | U22: =IF(Entries!V22='Correct Answers'!B22,2,0) -> 0 | V22: =Entries!W22-'Correct Answers'!B23 -> 173
A23: =Entries!A23 -> Alan Bennett | B23: =SUM(E23:U23) -> 0 | E23: =IF(Entries!B23='Correct Answers'!B2,2,0) -> 0 | F23: =IF(Entries!C23='Correct Answers'!B3,2,0) -> 0 | G23: =IF(Entries!D23='Correct Answers'!B4,2,0) -> 0 | H23: =IF(Entries!E23='Correct Answers'!B5,2,0) -> 0 | I23: =IF(Entries!F23='Correct Answers'!B6,2,0) -> 0 | J23: =IF(Entries!G23='Correct Answers'!B7,2,0) -> 0 | K23: =IF(Entries!H23='Correct Answers'!B8,2,0) -> 0 | L23: =IF(Entries!I23='Correct Answers'!B9,2,0) -> 0 | M23: =IF(Entries!J23='Correct Answers'!B10,2,0) -> 0 | N23: =IF(Entries!K23='Correct Answers'!B11,2,0) -> 0 | O23: =IF(Entries!L23='Correct Answers'!B12,2,0) -> 0 | P23: =IF(Entries!M23='Correct Answers'!B13,2,0) -> 0 | Q23: =2*(IF(Entries!N23='Correct Answers'!B14,1,0)+IF(Entries!O23='Correct Answers'!B15,1,0)+IF(Entries!P23='Correct Answers'!B16,1,0)+IF(Entries!Q23='Correct Answers'!B17,1,0)) -> 0 | R23: =2*(IF(Entries!R23='Correct Answers'!B18,1,0)+IF(Entries!S23='Correct Answers'!B19,1,0)) -> 0 | S23: =IF(Entries!T23='Correct Answers'!B20,2,0) -> 0 | T23: =IF(Entries!U23='Correct Answers'!B21,2,0) -> 0 | U23: =IF(Entries!V23='Correct Answers'!B22,2,0) -> 0 | V23: =Entries!W23-'Correct Answers'!B23 -> #VALUE!
A24: =Entries!A24 -> Matthew Varney | B24: =SUM(E24:U24) -> 0 | E24: =IF(Entries!B24='Correct Answers'!B2,2,0) -> 0 | F24: =IF(Entries!C24='Correct Answers'!B3,2,0) -> 0 | G24: =IF(Entries!D24='Correct Answers'!B4,2,0) -> 0 | H24: =IF(Entries!E24='Correct Answers'!B5,2,0) -> 0 | I24: =IF(Entries!F24='Correct Answers'!B6,2,0) -> 0 | J24: =IF(Entries!G24='Correct Answers'!B7,2,0) -> 0 | K24: =IF(Entries!H24='Correct Answers'!B8,2,0) -> 0 | L24: =IF(Entries!I24='Correct Answers'!B9,2,0) -> 0 | M24: =IF(Entries!J24='Correct Answers'!B10,2,0) -> 0 | N24: =IF(Entries!K24='Correct Answers'!B11,2,0) -> 0 | O24: =IF(Entries!L24='Correct Answers'!B12,2,0) -> 0 | P24: =IF(Entries!M24='Correct Answers'!B13,2,0) -> 0 | Q24: =2*(IF(Entries!N24='Correct Answers'!B14,1,0)+IF(Entries!O24='Correct Answers'!B15,1,0)+IF(Entries!P24='Correct Answers'!B16,1,0)+IF(Entries!Q24='Correct Answers'!B17,1,0)) -> 0 | R24: =2*(IF(Entries!R24='Correct Answers'!B18,1,0)+IF(Entries!S24='Correct Answers'!B19,1,0)) -> 0 | S24: =IF(Entries!T24='Correct Answers'!B20,2,0) -> 0 | T24: =IF(Entries!U24='Correct Answers'!B21,2,0) -> 0 | U24: =IF(Entries!V24='Correct Answers'!B22,2,0) -> 0 | V24: =Entries!W24-'Correct Answers'!B23 -> 185
A25: =Entries!A25 -> Oliver Nay | B25: =SUM(E25:U25) -> 0 | E25: =IF(Entries!B25='Correct Answers'!B2,2,0) -> 0 | F25: =IF(Entries!C25='Correct Answers'!B3,2,0) -> 0 | G25: =IF(Entries!D25='Correct Answers'!B4,2,0) -> 0 | H25: =IF(Entries!E25='Correct Answers'!B5,2,0) -> 0 | I25: =IF(Entries!F25='Correct Answers'!B6,2,0) -> 0 | J25: =IF(Entries!G25='Correct Answers'!B7,2,0) -> 0 | K25: =IF(Entries!H25='Correct Answers'!B8,2,0) -> 0 | L25: =IF(Entries!I25='Correct Answers'!B9,2,0) -> 0 | M25: =IF(Entries!J25='Correct Answers'!B10,2,0) -> 0 | N25: =IF(Entries!K25='Correct Answers'!B11,2,0) -> 0 | O25: =IF(Entries!L25='Correct Answers'!B12,2,0) -> 0 | P25: =IF(Entries!M25='Correct Answers'!B13,2,0) -> 0 | Q25: =2*(IF(Entries!N25='Correct Answers'!B14,1,0)+IF(Entries!O25='Correct Answers'!B15,1,0)+IF(Entries!P25='Correct Answers'!B16,1,0)+IF(Entries!Q25='Correct Answers'!B17,1,0)) -> 0 | R25: =2*(IF(Entries!R25='Correct Answers'!B18,1,0)+IF(Entries!S25='Correct Answers'!B19,1,0)) -> 0 | S25: =IF(Entries!T25='Correct Answers'!B20,2,0) -> 0 | T25: =IF(Entries!U25='Correct Answers'!B21,2,0) -> 0 | U25: =IF(Entries!V25='Correct Answers'!B22,2,0) -> 0 | V25: =Entries!W25-'Correct Answers'!B23 -> 45
A26: =Entries!A26 -> Stephen Roberts | B26: =SUM(E26:U26) -> 0 | E26: =IF(Entries!B26='Correct Answers'!B2,2,0) -> 0 | F26: =IF(Entries!C26='Correct Answers'!B3,2,0) -> 0 | G26: =IF(Entries!D26='Correct Answers'!B4,2,0) -> 0 | H26: =IF(Entries!E26='Correct Answers'!B5,2,0) -> 0 | I26: =IF(Entries!F26='Correct Answers'!B6,2,0) -> 0 | J26: =IF(Entries!G26='Correct Answers'!B7,2,0) -> 0 | K26: =IF(Entries!H26='Correct Answers'!B8,2,0) -> 0 | L26: =IF(Entries!I26='Correct Answers'!B9,2,0) -> 0 | M26: =IF(Entries!J26='Correct Answers'!B10,2,0) -> 0 | N26: =IF(Entries!K26='Correct Answers'!B11,2,0) -> 0 | O26: =IF(Entries!L26='Correct Answers'!B12,2,0) -> 0 | P26: =IF(Entries!M26='Correct Answers'!B13,2,0) -> 0 | Q26: =2*(IF(Entries!N26='Correct Answers'!B14,1,0)+IF(Entries!O26='Correct Answers'!B15,1,0)+IF(Entries!P26='Correct Answers'!B16,1,0)+IF(Entries!Q26='Correct Answers'!B17,1,0)) -> 0 | R26: =2*(IF(Entries!R26='Correct Answers'!B18,1,0)+IF(Entries!S26='Correct Answers'!B19,1,0)) -> 0 | S26: =IF(Entries!T26='Correct Answers'!B20,2,0) -> 0 | T26: =IF(Entries!U26='Correct Answers'!B21,2,0) -> 0 | U26: =IF(Entries!V26='Correct Answers'!B22,2,0) -> 0 | V26: =Entries!W26-'Correct Answers'!B23 -> 64
A27: =Entries!A27 -> Ethan Yates | B27: =SUM(E27:U27) -> 0 | E27: =IF(Entries!B27='Correct Answers'!B2,2,0) -> 0 | F27: =IF(Entries!C27='Correct Answers'!B3,2,0) -> 0 | G27: =IF(Entries!D27='Correct Answers'!B4,2,0) -> 0 | H27: =IF(Entries!E27='Correct Answers'!B5,2,0) -> 0 | I27: =IF(Entries!F27='Correct Answers'!B6,2,0) -> 0 | J27: =IF(Entries!G27='Correct Answers'!B7,2,0) -> 0 | K27: =IF(Entries!H27='Correct Answers'!B8,2,0) -> 0 | L27: =IF(Entries!I27='Correct Answers'!B9,2,0) -> 0 | M27: =IF(Entries!J27='Correct Answers'!B10,2,0) -> 0 | N27: =IF(Entries!K27='Correct Answers'!B11,2,0) -> 0 | O27: =IF(Entries!L27='Correct Answers'!B12,2,0) -> 0 | P27: =IF(Entries!M27='Correct Answers'!B13,2,0) -> 0 | Q27: =2*(IF(Entries!N27='Correct Answers'!B14,1,0)+IF(Entries!O27='Correct Answers'!B15,1,0)+IF(Entries!P27='Correct Answers'!B16,1,0)+IF(Entries!Q27='Correct Answers'!B17,1,0)) -> 0 | R27: =2*(IF(Entries!R27='Correct Answers'!B18,1,0)+IF(Entries!S27='Correct Answers'!B19,1,0)) -> 0 | S27: =IF(Entries!T27='Correct Answers'!B20,2,0) -> 0 | T27: =IF(Entries!U27='Correct Answers'!B21,2,0) -> 0 | U27: =IF(Entries!V27='Correct Answers'!B22,2,0) -> 0 | V27: =Entries!W27-'Correct Answers'!B23 -> 227
A28: =Entries!A28 -> Neil Keelan | B28: =SUM(E28:U28) -> 2 | E28: =IF(Entries!B28='Correct Answers'!B2,2,0) -> 0 | F28: =IF(Entries!C28='Correct Answers'!B3,2,0) -> 0 | G28: =IF(Entries!D28='Correct Answers'!B4,2,0) -> 0 | H28: =IF(Entries!E28='Correct Answers'!B5,2,0) -> 0 | I28: =IF(Entries!F28='Correct Answers'!B6,2,0) -> 0 | J28: =IF(Entries!G28='Correct Answers'!B7,2,0) -> 0 | K28: =IF(Entries!H28='Correct Answers'!B8,2,0) -> 0 | L28: =IF(Entries!I28='Correct Answers'!B9,2,0) -> 0 | M28: =IF(Entries!J28='Correct Answers'!B10,2,0) -> 0 | N28: =IF(Entries!K28='Correct Answers'!B11,2,0) -> 0 | O28: =IF(Entries!L28='Correct Answers'!B12,2,0) -> 0 | P28: =IF(Entries!M28='Correct Answers'!B13,2,0) -> 0 | Q28: =2*(IF(Entries!N28='Correct Answers'!B14,1,0)+IF(Entries!O28='Correct Answers'!B15,1,0)+IF(Entries!P28='Correct Answers'!B16,1,0)+IF(Entries!Q28='Correct Answers'!B17,1,0)) -> 0 | R28: =2*(IF(Entries!R28='Correct Answers'!B18,1,0)+IF(Entries!S28='Correct Answers'!B19,1,0)) -> 0 | S28: =IF(Entries!T28='Correct Answers'!B20,2,0) -> 0 | T28: =IF(Entries!U28='Correct Answers'!B21,2,0) -> 0 | U28: =IF(Entries!V28='Correct Answers'!B22,2,0) -> 2 | V28: =Entries!W28-'Correct Answers'!B23 -> 222
A29: =Entries!A29 -> Terresa Baker | B29: =SUM(E29:U29) -> 0 | E29: =IF(Entries!B29='Correct Answers'!B2,2,0) -> 0 | F29: =IF(Entries!C29='Correct Answers'!B3,2,0) -> 0 | G29: =IF(Entries!D29='Correct Answers'!B4,2,0) -> 0 | H29: =IF(Entries!E29='Correct Answers'!B5,2,0) -> 0 | I29: =IF(Entries!F29='Correct Answers'!B6,2,0) -> 0 | J29: =IF(Entries!G29='Correct Answers'!B7,2,0) -> 0 | K29: =IF(Entries!H29='Correct Answers'!B8,2,0) -> 0 | L29: =IF(Entries!I29='Correct Answers'!B9,2,0) -> 0 | M29: =IF(Entries!J29='Correct Answers'!B10,2,0) -> 0 | N29: =IF(Entries!K29='Correct Answers'!B11,2,0) -> 0 | O29: =IF(Entries!L29='Correct Answers'!B12,2,0) -> 0 | P29: =IF(Entries!M29='Correct Answers'!B13,2,0) -> 0 | Q29: =2*(IF(Entries!N29='Correct Answers'!B14,1,0)+IF(Entries!O29='Correct Answers'!B15,1,0)+IF(Entries!P29='Correct Answers'!B16,1,0)+IF(Entries!Q29='Correct Answers'!B17,1,0)) -> 0 | R29: =2*(IF(Entries!R29='Correct Answers'!B18,1,0)+IF(Entries!S29='Correct Answers'!B19,1,0)) -> 0 | S29: =IF(Entries!T29='Correct Answers'!B20,2,0) -> 0 | T29: =IF(Entries!U29='Correct Answers'!B21,2,0) -> 0 | U29: =IF(Entries!V29='Correct Answers'!B22,2,0) -> 0 | V29: =Entries!W29-'Correct Answers'!B23 -> 204
A30: =Entries!A30 -> Steph Cawte | B30: =SUM(E30:U30) -> 0 | E30: =IF(Entries!B30='Correct Answers'!B2,2,0) -> 0 | F30: =IF(Entries!C30='Correct Answers'!B3,2,0) -> 0 | G30: =IF(Entries!D30='Correct Answers'!B4,2,0) -> 0 | H30: =IF(Entries!E30='Correct Answers'!B5,2,0) -> 0 | I30: =IF(Entries!F30='Correct Answers'!B6,2,0) -> 0 | J30: =IF(Entries!G30='Correct Answers'!B7,2,0) -> 0 | K30: =IF(Entries!H30='Correct Answers'!B8,2,0) -> 0 | L30: =IF(Entries!I30='Correct Answers'!B9,2,0) -> 0 | M30: =IF(Entries!J30='Correct Answers'!B10,2,0) -> 0 | N30: =IF(Entries!K30='Correct Answers'!B11,2,0) -> 0 | O30: =IF(Entries!L30='Correct Answers'!B12,2,0) -> 0 | P30: =IF(Entries!M30='Correct Answers'!B13,2,0) -> 0 | Q30: =2*(IF(Entries!N30='Correct Answers'!B14,1,0)+IF(Entries!O30='Correct Answers'!B15,1,0)+IF(Entries!P30='Correct Answers'!B16,1,0)+IF(Entries!Q30='Correct Answers'!B17,1,0)) -> 0 | R30: =2*(IF(Entries!R30='Correct Answers'!B18,1,0)+IF(Entries!S30='Correct Answers'!B19,1,0)) -> 0 | S30: =IF(Entries!T30='Correct Answers'!B20,2,0) -> 0 | T30: =IF(Entries!U30='Correct Answers'!B21,2,0) -> 0 | U30: =IF(Entries!V30='Correct Answers'!B22,2,0) -> 0 | V30: =Entries!W30-'Correct Answers'!B23 -> 131
A31: =Entries!A31 -> Sam Flower | B31: =SUM(E31:U31) -> 0 | E31: =IF(Entries!B31='Correct Answers'!B2,2,0) -> 0 | F31: =IF(Entries!C31='Correct Answers'!B3,2,0) -> 0 | G31: =IF(Entries!D31='Correct Answers'!B4,2,0) -> 0 | H31: =IF(Entries!E31='Correct Answers'!B5,2,0) -> 0 | I31: =IF(Entries!F31='Correct Answers'!B6,2,0) -> 0 | J31: =IF(Entries!G31='Correct Answers'!B7,2,0) -> 0 | K31: =IF(Entries!H31='Correct Answers'!B8,2,0) -> 0 | L31: =IF(Entries!I31='Correct Answers'!B9,2,0) -> 0 | M31: =IF(Entries!J31='Correct Answers'!B10,2,0) -> 0 | N31: =IF(Entries!K31='Correct Answers'!B11,2,0) -> 0 | O31: =IF(Entries!L31='Correct Answers'!B12,2,0) -> 0 | P31: =IF(Entries!M31='Correct Answers'!B13,2,0) -> 0 | Q31: =2*(IF(Entries!N31='Correct Answers'!B14,1,0)+IF(Entries!O31='Correct Answers'!B15,1,0)+IF(Entries!P31='Correct Answers'!B16,1,0)+IF(Entries!Q31='Correct Answers'!B17,1,0)) -> 0 | R31: =2*(IF(Entries!R31='Correct Answers'!B18,1,0)+IF(Entries!S31='Correct Answers'!B19,1,0)) -> 0 | S31: =IF(Entries!T31='Correct Answers'!B20,2,0) -> 0 | T31: =IF(Entries!U31='Correct Answers'!B21,2,0) -> 0 | U31: =IF(Entries!V31='Correct Answers'!B22,2,0) -> 0 | V31: =Entries!W31-'Correct Answers'!B23 -> 165
A32: =Entries!A32 -> Martin Fallon | B32: =SUM(E32:U32) -> 0 | E32: =IF(Entries!B32='Correct Answers'!B2,2,0) -> 0 | F32: =IF(Entries!C32='Correct Answers'!B3,2,0) -> 0 | G32: =IF(Entries!D32='Correct Answers'!B4,2,0) -> 0 | H32: =IF(Entries!E32='Correct Answers'!B5,2,0) -> 0 | I32: =IF(Entries!F32='Correct Answers'!B6,2,0) -> 0 | J32: =IF(Entries!G32='Correct Answers'!B7,2,0) -> 0 | K32: =IF(Entries!H32='Correct Answers'!B8,2,0) -> 0 | L32: =IF(Entries!I32='Correct Answers'!B9,2,0) -> 0 | M32: =IF(Entries!J32='Correct Answers'!B10,2,0) -> 0 | N32: =IF(Entries!K32='Correct Answers'!B11,2,0) -> 0 | O32: =IF(Entries!L32='Correct Answers'!B12,2,0) -> 0 | P32: =IF(Entries!M32='Correct Answers'!B13,2,0) -> 0 | Q32: =2*(IF(Entries!N32='Correct Answers'!B14,1,0)+IF(Entries!O32='Correct Answers'!B15,1,0)+IF(Entries!P32='Correct Answers'!B16,1,0)+IF(Entries!Q32='Correct Answers'!B17,1,0)) -> 0 | R32: =2*(IF(Entries!R32='Correct Answers'!B18,1,0)+IF(Entries!S32='Correct Answers'!B19,1,0)) -> 0 | S32: =IF(Entries!T32='Correct Answers'!B20,2,0) -> 0 | T32: =IF(Entries!U32='Correct Answers'!B21,2,0) -> 0 | U32: =IF(Entries!V32='Correct Answers'!B22,2,0) -> 0 | V32: =Entries!W32-'Correct Answers'!B23 -> 253
A33: =Entries!A33 -> Ed Burthem | B33: =SUM(E33:U33) -> 2 | E33: =IF(Entries!B33='Correct Answers'!B2,2,0) -> 0 | F33: =IF(Entries!C33='Correct Answers'!B3,2,0) -> 0 | G33: =IF(Entries!D33='Correct Answers'!B4,2,0) -> 0 | H33: =IF(Entries!E33='Correct Answers'!B5,2,0) -> 0 | I33: =IF(Entries!F33='Correct Answers'!B6,2,0) -> 0 | J33: =IF(Entries!G33='Correct Answers'!B7,2,0) -> 0 | K33: =IF(Entries!H33='Correct Answers'!B8,2,0) -> 0 | L33: =IF(Entries!I33='Correct Answers'!B9,2,0) -> 0 | M33: =IF(Entries!J33='Correct Answers'!B10,2,0) -> 0 | N33: =IF(Entries!K33='Correct Answers'!B11,2,0) -> 0 | O33: =IF(Entries!L33='Correct Answers'!B12,2,0) -> 0 | P33: =IF(Entries!M33='Correct Answers'!B13,2,0) -> 0 | Q33: =2*(IF(Entries!N33='Correct Answers'!B14,1,0)+IF(Entries!O33='Correct Answers'!B15,1,0)+IF(Entries!P33='Correct Answers'!B16,1,0)+IF(Entries!Q33='Correct Answers'!B17,1,0)) -> 0 | R33: =2*(IF(Entries!R33='Correct Answers'!B18,1,0)+IF(Entries!S33='Correct Answers'!B19,1,0)) -> 0 | S33: =IF(Entries!T33='Correct Answers'!B20,2,0) -> 0 | T33: =IF(Entries!U33='Correct Answers'!B21,2,0) -> 0 | U33: =IF(Entries!V33='Correct Answers'!B22,2,0) -> 2 | V33: =Entries!W33-'Correct Answers'!B23 -> 180
A34: =Entries!A34 -> Dylan Green | B34: =SUM(E34:U34) -> 0 | E34: =IF(Entries!B34='Correct Answers'!B2,2,0) -> 0 | F34: =IF(Entries!C34='Correct Answers'!B3,2,0) -> 0 | G34: =IF(Entries!D34='Correct Answers'!B4,2,0) -> 0 | H34: =IF(Entries!E34='Correct Answers'!B5,2,0) -> 0 | I34: =IF(Entries!F34='Correct Answers'!B6,2,0) -> 0 | J34: =IF(Entries!G34='Correct Answers'!B7,2,0) -> 0 | K34: =IF(Entries!H34='Correct Answers'!B8,2,0) -> 0 | L34: =IF(Entries!I34='Correct Answers'!B9,2,0) -> 0 | M34: =IF(Entries!J34='Correct Answers'!B10,2,0) -> 0 | N34: =IF(Entries!K34='Correct Answers'!B11,2,0) -> 0 | O34: =IF(Entries!L34='Correct Answers'!B12,2,0) -> 0 | P34: =IF(Entries!M34='Correct Answers'!B13,2,0) -> 0 | Q34: =2*(IF(Entries!N34='Correct Answers'!B14,1,0)+IF(Entries!O34='Correct Answers'!B15,1,0)+IF(Entries!P34='Correct Answers'!B16,1,0)+IF(Entries!Q34='Correct Answers'!B17,1,0)) -> 0 | R34: =2*(IF(Entries!R34='Correct Answers'!B18,1,0)+IF(Entries!S34='Correct Answers'!B19,1,0)) -> 0 | S34: =IF(Entries!T34='Correct Answers'!B20,2,0) -> 0 | T34: =IF(Entries!U34='Correct Answers'!B21,2,0) -> 0 | U34: =IF(Entries!V34='Correct Answers'!B22,2,0) -> 0 | V34: =Entries!W34-'Correct Answers'!B23 -> 241
A35: =Entries!A35 -> Matthew Green | B35: =SUM(E35:U35) -> 0 | E35: =IF(Entries!B35='Correct Answers'!B2,2,0) -> 0 | F35: =IF(Entries!C35='Correct Answers'!B3,2,0) -> 0 | G35: =IF(Entries!D35='Correct Answers'!B4,2,0) -> 0 | H35: =IF(Entries!E35='Correct Answers'!B5,2,0) -> 0 | I35: =IF(Entries!F35='Correct Answers'!B6,2,0) -> 0 | J35: =IF(Entries!G35='Correct Answers'!B7,2,0) -> 0 | K35: =IF(Entries!H35='Correct Answers'!B8,2,0) -> 0 | L35: =IF(Entries!I35='Correct Answers'!B9,2,0) -> 0 | M35: =IF(Entries!J35='Correct Answers'!B10,2,0) -> 0 | N35: =IF(Entries!K35='Correct Answers'!B11,2,0) -> 0 | O35: =IF(Entries!L35='Correct Answers'!B12,2,0) -> 0 | P35: =IF(Entries!M35='Correct Answers'!B13,2,0) -> 0 | Q35: =2*(IF(Entries!N35='Correct Answers'!B14,1,0)+IF(Entries!O35='Correct Answers'!B15,1,0)+IF(Entries!P35='Correct Answers'!B16,1,0)+IF(Entries!Q35='Correct Answers'!B17,1,0)) -> 0 | R35: =2*(IF(Entries!R35='Correct Answers'!B18,1,0)+IF(Entries!S35='Correct Answers'!B19,1,0)) -> 0 | S35: =IF(Entries!T35='Correct Answers'!B20,2,0) -> 0 | T35: =IF(Entries!U35='Correct Answers'!B21,2,0) -> 0 | U35: =IF(Entries!V35='Correct Answers'!B22,2,0) -> 0 | V35: =Entries!W35-'Correct Answers'!B23 -> -24
A36: =Entries!A36 -> Thomas Green | B36: =SUM(E36:U36) -> 0 | E36: =IF(Entries!B36='Correct Answers'!B2,2,0) -> 0 | F36: =IF(Entries!C36='Correct Answers'!B3,2,0) -> 0 | G36: =IF(Entries!D36='Correct Answers'!B4,2,0) -> 0 | H36: =IF(Entries!E36='Correct Answers'!B5,2,0) -> 0 | I36: =IF(Entries!F36='Correct Answers'!B6,2,0) -> 0 | J36: =IF(Entries!G36='Correct Answers'!B7,2,0) -> 0 | K36: =IF(Entries!H36='Correct Answers'!B8,2,0) -> 0 | L36: =IF(Entries!I36='Correct Answers'!B9,2,0) -> 0 | M36: =IF(Entries!J36='Correct Answers'!B10,2,0) -> 0 | N36: =IF(Entries!K36='Correct Answers'!B11,2,0) -> 0 | O36: =IF(Entries!L36='Correct Answers'!B12,2,0) -> 0 | P36: =IF(Entries!M36='Correct Answers'!B13,2,0) -> 0 | Q36: =2*(IF(Entries!N36='Correct Answers'!B14,1,0)+IF(Entries!O36='Correct Answers'!B15,1,0)+IF(Entries!P36='Correct Answers'!B16,1,0)+IF(Entries!Q36='Correct Answers'!B17,1,0)) -> 0 | R36: =2*(IF(Entries!R36='Correct Answers'!B18,1,0)+IF(Entries!S36='Correct Answers'!B19,1,0)) -> 0 | S36: =IF(Entries!T36='Correct Answers'!B20,2,0) -> 0 | T36: =IF(Entries!U36='Correct Answers'!B21,2,0) -> 0 | U36: =IF(Entries!V36='Correct Answers'!B22,2,0) -> 0 | V36: =Entries!W36-'Correct Answers'!B23 -> 312
